<?xml version="1.0"?>
<robot name="desalination_gazebo">

<link name="base_footprint">
  <visual>
    <origin xyz="0 0 0" rpy="0 0 0" />
    <geometry>
      <box size="0.0005 0.0005 0.00001" />
    </geometry>
  </visual>
</link>

<joint name="base_joint" type="fixed">
  <origin xyz="0 0 0" rpy="0 0 0" />
  <parent link="base_footprint"/>
  <child link="base_link" />
</joint>

<!-- body -->
<link name = "base_link">
  <visual>
    <origin xyz="0 0 0" rpy="0 0 0" />
    <geometry>
      <box size="0.6 0.6 0.4" />
    </geometry>
  </visual>
  <collision>
    <origin xyz="0 0 0" rpy="0 0 0" />
    <geometry>
      <box size="0.6 0.6 0.4" />
    </geometry>
  </collision>
  <inertial>
    <mass value="70"/>
    <inertia ixx="4.00538" ixy="0.0" ixz="0.0" iyy="4.00538" iyz="0.0" izz="0.51076"/>
  </inertial>
</link>

<!-- wheels-->
<link name = "left_front_wheel">
  <visual>
    <origin xyz="0 0 0" rpy="0 0 0" />
    <geometry>
      <cylinder length="0.1" radius="0.15" />
    </geometry>
  </visual>
  <collision>
    <origin xyz="0 0 0" rpy="0 0 0" />
    <geometry>
      <cylinder length="0.1" radius="0.15" />
    </geometry>
  </collision>
  <inertial>
    <mass value="1"/>
    <inertia ixx="0.145833" ixy="0.0" ixz="0.0" iyy="0.145833" iyz="0.0" izz="0.125"/>
  </inertial>
</link>
<joint name="left_front_wheel_joint" type="continuous">
  <axis xyz="0 0 1"/>
  <limit effort="100000.0" lower="-1.79769e+308" upper="1.79769e+308" velocity="1"/>
  <origin xyz="0.2 0.3 -0.15" rpy="1.5707 0 0" />
  <parent link="base_link"/>
  <child link="left_front_wheel" />
</joint>

<link name = "left_back_wheel">
  <visual>
    <origin xyz="0 0 0" rpy="0 0 0" />
    <geometry>
      <cylinder length="0.1" radius="0.15" />
    </geometry>
  </visual>
  <collision>
    <origin xyz="0 0 0" rpy="0 0 0" />
    <geometry>
      <cylinder length="0.1" radius="0.15" />
    </geometry>
  </collision>
  <inertial>
    <mass value="1"/>
    <inertia ixx="0.145833" ixy="0.0" ixz="0.0" iyy="0.145833" iyz="0.0" izz="0.125"/>
  </inertial>
</link>
<joint name="left_back_wheel_joint" type="continuous">
  <axis xyz="0 0 1"/>
  <limit effort="100000.0" lower="-1.79769e+308" upper="1.79769e+308" velocity="1"/>
  <origin xyz="-0.2 0.3 -0.15" rpy="1.5707 0 0" />
  <parent link="base_link"/>
  <child link="left_back_wheel" />
</joint>

<link name = "right_front_wheel">
  <visual>
    <origin xyz="0 0 0" rpy="0 0 0" />
    <geometry>
      <cylinder length="0.1" radius="0.15" />
    </geometry>
  </visual>
  <collision>
    <origin xyz="0 0 0" rpy="0 0 0" />
    <geometry>
      <cylinder length="0.1" radius="0.15" />
    </geometry>
  </collision>
  <inertial>
    <mass value="1"/>
    <inertia ixx="0.145833" ixy="0.0" ixz="0.0" iyy="0.145833" iyz="0.0" izz="0.125"/>
  </inertial>
</link>
<joint name="right_front_wheel_joint" type="continuous">
  <axis xyz="0 0 1"/>
  <limit effort="100000.0" lower="-1.79769e+308" upper="1.79769e+308" velocity="1"/>
  <origin xyz="0.2 -0.3 -0.15" rpy="1.5707 0 0" />
  <parent link="base_link"/>
  <child link="right_front_wheel" />
</joint>

<link name = "right_back_wheel">
  <visual>
    <origin xyz="0 0 0" rpy="0 0 0" />
    <geometry>
      <cylinder length="0.1" radius="0.15" />
    </geometry>
  </visual>
  <collision>
    <origin xyz="0 0 0" rpy="0 0 0" />
    <geometry>
      <cylinder length="0.1" radius="0.15" />
    </geometry>
  </collision>
  <inertial>
    <mass value="1"/>
    <inertia ixx="0.145833" ixy="0.0" ixz="0.0" iyy="0.145833" iyz="0.0" izz="0.125"/>
  </inertial>
</link>
<joint name="right_back_wheel_joint" type="continuous">
  <axis xyz="0 0 1"/>
  <limit effort="100000.0" lower="-1.79769e+308" upper="1.79769e+308" velocity="1"/>
  <origin xyz="-0.2 -0.3 -0.15" rpy="1.5707 0 0" />
  <parent link="base_link"/>
  <child link="right_back_wheel" />
</joint>

<!-- Lidar -->
<link name = "laser">
  <visual>
   <geometry>
      <cylinder length="0.04" radius="0.02"/>
   </geometry>
   <origin rpy = "0 0 0" xyz = "0 0 0"/>
  </visual>
</link>
<joint name="laser_joint" type="fixed">
    <origin rpy="0 0 0" xyz="0 0 0.2"  /> <!--pos-->
    <parent link="base_link" />
    <child link="laser" />
</joint>

<!-- imu -->
<link name = "imu_link">
  <visual>
   <geometry>
      <cylinder length="0.04" radius="0.02"/>
   </geometry>
   <origin rpy = "0 0 0" xyz = "0 0 0"/>
  </visual>
</link>
<joint name="imu_joint" type="fixed">
    <origin rpy="0 0 0" xyz="0 0 0.2"  /> <!--pos-->
    <parent link="base_link" />
    <child link="imu_link" />
</joint>



<!-- Gazebo plugin for WPR -->
<gazebo>
  <plugin name="base_controller" filename="libwpr_plugin.so">
    <publishOdometryTf>true</publishOdometryTf>
    <commandTopic>cmd_vel</commandTopic>
    <odometryTopic>odom</odometryTopic>
    <odometryFrame>odom</odometryFrame>
    <odometryRate>50.0</odometryRate>
    <robotBaseFrame>base_footprint</robotBaseFrame>
  </plugin>
</gazebo>

<!-- Gazebo plugin for RpLidar A2 -->
<gazebo reference="laser">
  <sensor type="ray" name="rplidar_sensor">
    <pose>0 0 0.06 0 0 0</pose>
    <visualize>true</visualize>
    <update_rate>50</update_rate>
    <ray>
      <scan>
        <horizontal>
          <samples>360</samples>
          <resolution>1</resolution>
          <min_angle>-3.14159265</min_angle>
          <max_angle>3.14159265</max_angle>
        </horizontal>
      </scan>
      <range>
        <min>0.24</min>
        <max>200.0</max>
        <resolution>0.01</resolution>
      </range>
      <noise>
        <type>gaussian</type>
        <mean>0.0</mean>
        <stddev>0.01</stddev>
      </noise>
    </ray>
    <plugin name="rplidar_ros_controller" filename="libgazebo_ros_laser.so">
      <topicName>scan</topicName>
      <frameName>laser</frameName>
    </plugin>
  </sensor>
</gazebo>



<!-- IMU plugin for 'body_link' -->
<gazebo reference="base_link">
  <gravity>true</gravity>
  <sensor name="imu_sensor" type="imu">
    <always_on>true</always_on>
    <update_rate>50</update_rate>
    <visualize>true</visualize>
    <topic>__default_topic__</topic>
    <plugin filename="libgazebo_ros_imu_sensor.so" name="imu_plugin">
      <topicName>imu</topicName>
      <bodyName>base_link</bodyName>
      <updateRateHZ>50.0</updateRateHZ>
      <gaussianNoise>0.0</gaussianNoise>
      <xyzOffset>0 0 0</xyzOffset>
      <rpyOffset>0 0 0</rpyOffset>
      <frameName>imu_link</frameName>
    </plugin>
    <pose>0 0 0 0 0 0</pose>
  </sensor>
</gazebo>

</robot>
