<?xml version="1.0" ?>
<robot name="mrobot_chassis">

    <link name="base_link">
        <visual>
            <origin xyz=" 0 0 0" rpy="0 0 0" />
            <geometry>
                <box size="0.6 0.6 0.4" />
            </geometry>
            <material name="yellow">
                <color rgba="1 0.4 0 1"/>
            </material>
        </visual>
    </link>

    <joint name="base_leftback_motor_joint" type="fixed">
        <origin xyz="-0.2 0.16 -0.2" rpy="0 0 0" />        
        <parent link="base_link"/>
        <child link="leftback_motor" />
    </joint>

    <link name="leftback_motor">
        <visual>
            <origin xyz="0 0 0" rpy="1.5707 0 0" />
            <geometry>
                <cylinder radius="0.05" length = "0.29"/>
            </geometry>
            <material name="gray">
                <color rgba="0.75 0.75 0.75 1"/>
            </material>
        </visual>
    </link>

    <joint name="leftback_wheel_joint" type="continuous">
        <origin xyz="0 0.19 0" rpy="0 0 0"/>
        <parent link="leftback_motor"/>
        <child link="leftback_wheel_link"/>
        <axis xyz="0 1 0"/>
    </joint>

    <link name="leftback_wheel_link">
        <visual>
            <origin xyz="0 0 0" rpy="1.5707 0 0" />
            <geometry>
                <cylinder radius="0.15" length = "0.1"/>
            </geometry>
            <material name="white">
                <color rgba="1 1 1 0.9"/>
            </material>
        </visual>
    </link>

    <joint name="base_rightback_motor_joint" type="fixed">
        <origin xyz="-0.2 -0.16 -0.2" rpy="0 0 0" />        
        <parent link="base_link"/>
        <child link="rightback_motor" />
    </joint>

    <link name="rightback_motor">
        <visual>
            <origin xyz="0 0 0" rpy="1.5707 0 0" />
            <geometry>
                <cylinder radius="0.05" length = "0.29"/>
            </geometry>
            <material name="gray">
                <color rgba="0.75 0.75 0.75 1"/>
            </material>
        </visual>
    </link>

    <joint name="rightback_wheel_joint" type="continuous">
        <origin xyz="0 -0.19 0" rpy="0 0 0"/>
        <parent link="rightback_motor"/>
        <child link="rightback_wheel_link"/>
        <axis xyz="0 1 0"/>
    </joint>

    <link name="rightback_wheel_link">
        <visual>
            <origin xyz="0 0 0" rpy="1.5707 0 0" />
            <geometry>
                <cylinder radius="0.15" length = "0.1"/>
            </geometry>
            <material name="white">
                <color rgba="1 1 1 0.9"/>
            </material>
        </visual>
    </link>

    <joint name="base_leftforwatd_motor_joint" type="fixed">
        <origin xyz="0.2 0.16 -0.2" rpy="0 0 0" />        
        <parent link="base_link"/>
        <child link="leftforward_motor" />
    </joint>

    <link name="leftforward_motor">
        <visual>
            <origin xyz="0 0 0" rpy="1.5707 0 0" />
            <geometry>
                <cylinder radius="0.05" length = "0.29"/>
            </geometry>
            <material name="gray">
                <color rgba="0.75 0.75 0.75 1"/>
            </material>
        </visual>
    </link>

    <joint name="leftforward_wheel_joint" type="continuous">
        <origin xyz="0 0.19 0" rpy="0 0 0"/>
        <parent link="leftforward_motor"/>
        <child link="leftforward_wheel_link"/>
        <axis xyz="0 1 0"/>
    </joint>

    <link name="leftforward_wheel_link">
        <visual>
            <origin xyz="0 0 0" rpy="1.5707 0 0" />
            <geometry>
                <cylinder radius="0.15" length = "0.1"/>
            </geometry>
            <material name="white">
                <color rgba="1 1 1 0.9"/>
            </material>
        </visual>
    </link>

    <joint name="base_rightforward_motor_joint" type="fixed">
        <origin xyz="0.2 -0.16 -0.2" rpy="0 0 0" />        
        <parent link="base_link"/>
        <child link="rightforward_motor" />
    </joint>

    <link name="rightforward_motor">
        <visual>
            <origin xyz="0 0 0" rpy="1.5707 0 0" />
            <geometry>
                <cylinder radius="0.05" length = "0.29"/>
            </geometry>
            <material name="gray">
                <color rgba="0.75 0.75 0.75 1"/>
            </material>
        </visual>
    </link>

    <joint name="rightforward_wheel_joint" type="continuous">
        <origin xyz="0 -0.19 0" rpy="0 0 0"/>
        <parent link="rightforward_motor"/>
        <child link="rightforward_wheel_link"/>
        <axis xyz="0 1 0"/>
    </joint>

    <link name="rightforward_wheel_link">
        <visual>
            <origin xyz="0 0 0" rpy="1.5707 0 0" />
            <geometry>
                <cylinder radius="0.15" length = "0.1"/>
            </geometry>
            <material name="white">
                <color rgba="1 1 1 0.9"/>
            </material>
        </visual>
    </link>

</robot>